<?xml version="1.0" encoding="UTF-8"?>
<!-- Generated by org.testng.reporters.JUnitReportReporter -->
<testsuite hostname="DESKTOP-MD6G5O7" failures="1" tests="3" name="TestNG.NewTest2" time="0.017" errors="0" timestamp="2020-03-24T13:35:34 IST" skipped="0">
  <testcase classname="TestNG.NewTest2" name="TestC" time="0.002"/>
  <system-out/>
  <testcase classname="TestNG.NewTest2" name="TestB" time="0.012">
    <failure message="expected [yahoo] but found [yahoo1]" type="java.lang.AssertionError">
      <![CDATA[java.lang.AssertionError: expected [yahoo] but found [yahoo1]
at org.testng.Assert.fail(Assert.java:97)
at org.testng.Assert.assertEqualsImpl(Assert.java:136)
at org.testng.Assert.assertEquals(Assert.java:118)
at org.testng.Assert.assertEquals(Assert.java:575)
at org.testng.Assert.assertEquals(Assert.java:585)
at TestNG.NewTest2.TestB(NewTest2.java:15)
at java.base/jdk.internal.reflect.NativeMethodAccessorImpl.invoke0(Native Method)
at java.base/jdk.internal.reflect.NativeMethodAccessorImpl.invoke(NativeMethodAccessorImpl.java:62)
at java.base/jdk.internal.reflect.DelegatingMethodAccessorImpl.invoke(DelegatingMethodAccessorImpl.java:43)
at java.base/java.lang.reflect.Method.invoke(Method.java:567)
at org.testng.internal.MethodInvocationHelper.invokeMethod(MethodInvocationHelper.java:134)
at org.testng.internal.InvokeMethodRunnable.runOne(InvokeMethodRunnable.java:47)
at org.testng.internal.InvokeMethodRunnable.call(InvokeMethodRunnable.java:68)
at org.testng.internal.InvokeMethodRunnable.call(InvokeMethodRunnable.java:13)
at java.base/java.util.concurrent.FutureTask.run(FutureTask.java:264)
at java.base/java.util.concurrent.ThreadPoolExecutor.runWorker(ThreadPoolExecutor.java:1128)
at java.base/java.util.concurrent.ThreadPoolExecutor$Worker.run(ThreadPoolExecutor.java:628)
at java.base/java.lang.Thread.run(Thread.java:830)
]]>
    </failure>
  </testcase> <!-- TestB -->
  <system-out/>
  <testcase classname="TestNG.NewTest2" name="TestA" time="0.003"/>
  <system-out/>
</testsuite> <!-- TestNG.NewTest2 -->
